Workbook

Sheet Data
A1: University | B1: Division | C1: Football participants | D1: Total Football expenses | E1: Overall wins | F1: Overall losses | G1: Conference wins | H1: Conference losses | I1: Expenses per participant | J1: Overall win percentage | K1: Conference win percentage | L1: Wins per $1M spent | M1: Conference wins per $1M spent | N1: Financial data source | O1: Sport results source
A2: Appalachian State University | B2: East | C2: 122 | D2: 13288981 | E2: 9 | F2: 5 | G2: 6 | H2: 2 | I2: =D2/C2 -> 108926.07 | J2: =E2/(E2+F2) -> 0.64285714 | K2: =G2/(G2+H2) -> 0.75 | L2: =E2/(D2/1000000) -> 0.67725283 | M2: =G2/(D2/1000000) -> 0.45150189 | N2: U.S. Department of Education — EADA Survey Year 2024 | O2: Sun Belt Conference – 2023 Football Standings
A3: Arkansas State University | B3: West | C3: 153 | D3: 11536628 | E3: 6 | F3: 7 | G3: 4 | H3: 4 | I3: =D3/C3 -> 75402.797 | J3: =E3/(E3+F3) -> 0.46153846 | K3: =G3/(G3+H3) -> 0.5 | L3: =E3/(D3/1000000) -> 0.52008264 | M3: =G3/(D3/1000000) -> 0.34672176 | N3: U.S. Department of Education — EADA Survey Year 2024 | O3: Sun Belt Conference – 2023 Football Standings
A4: Coastal Carolina University | B4: East | C4: 123 | D4: 17052582 | E4: 8 | F4: 5 | G4: 5 | H4: 3 | I4: =D4/C4 -> 138638.88 | J4: =E4/(E4+F4) -> 0.61538462 | K4: =G4/(G4+H4) -> 0.625 | L4: =E4/(D4/1000000) -> 0.46913717 | M4: =G4/(D4/1000000) -> 0.29321073 | N4: U.S. Department of Education — EADA Survey Year 2024 | O4: Sun Belt Conference – 2023 Football Standings
A5: Georgia Southern University | B5: East | C5: 146 | D5: 11225441 | E5: 6 | F5: 7 | G5: 3 | H5: 5 | I5: =D5/C5 -> 76886.582 | J5: =E5/(E5+F5) -> 0.46153846 | K5: =G5/(G5+H5) -> 0.375 | L5: =E5/(D5/1000000) -> 0.53450016 | M5: =G5/(D5/1000000) -> 0.26725008 | N5: U.S. Department of Education — EADA Survey Year 2024 | O5: Sun Belt Conference – 2023 Football Standings
A6: Georgia State University | B6: East | C6: 118 | D6: 12260120 | E6: 7 | F6: 6 | G6: 3 | H6: 5 | I6: =D6/C6 -> 103899.32 | J6: =E6/(E6+F6) -> 0.53846154 | K6: =G6/(G6+H6) -> 0.375 | L6: =E6/(D6/1000000) -> 0.57095689 | M6: =G6/(D6/1000000) -> 0.24469581 | N6: U.S. Department of Education — EADA Survey Year 2024 | O6: Sun Belt Conference – 2023 Football Standings
A7: James Madison University | B7: East | C7: 121 | D7: 16863958 | E7: 11 | F7: 2 | G7: 7 | H7: 1 | I7: =D7/C7 -> 139371.55 | J7: =E7/(E7+F7) -> 0.84615385 | K7: =G7/(G7+H7) -> 0.875 | L7: =E7/(D7/1000000) -> 0.65227866 | M7: =G7/(D7/1000000) -> 0.41508642 | N7: U.S. Department of Education — EADA Survey Year 2024 | O7: Sun Belt Conference – 2023 Football Standings
A8: Marshall University | B8: East | C8: 118 | D8: 13569649 | E8: 6 | F8: 7 | G8: 3 | H8: 5 | I8: =D8/C8 -> 114997.03 | J8: =E8/(E8+F8) -> 0.46153846 | K8: =G8/(G8+H8) -> 0.375 | L8: =E8/(D8/1000000) -> 0.44216324 | M8: =G8/(D8/1000000) -> 0.22108162 | N8: U.S. Department of Education — EADA Survey Year 2024 | O8: Sun Belt Conference – 2023 Football Standings
A9: Old Dominion University | B9: East | C9: 116 | D9: 14787371 | E9: 6 | F9: 7 | G9: 5 | H9: 3 | I9: =D9/C9 -> 127477.34 | J9: =E9/(E9+F9) -> 0.46153846 | K9: =G9/(G9+H9) -> 0.625 | L9: =E9/(D9/1000000) -> 0.40575164 | M9: =G9/(D9/1000000) -> 0.33812636 | N9: U.S. Department of Education — EADA Survey Year 2024 | O9: Sun Belt Conference – 2023 Football Standings
A10: University of Louisiana at Lafayette | B10: West | C10: 142 | D10: 14846554 | E10: 6 | F10: 7 | G10: 3 | H10: 5 | I10: =D10/C10 -> 104553.2 | J10: =E10/(E10+F10) -> 0.46153846 | K10: =G10/(G10+H10) -> 0.375 | L10: =E10/(D10/1000000) -> 0.40413418 | M10: =G10/(D10/1000000) -> 0.20206709 | N10: U.S. Department of Education — EADA Survey Year 2024 | O10: Sun Belt Conference – 2023 Football Standings
A11: University of Louisiana at Monroe | B11: West | C11: 117 | D11: 7772886 | E11: 2 | F11: 10 | G11: 0 | H11: 8 | I11: =D11/C11 -> 66434.923 | J11: =E11/(E11+F11) -> 0.16666667 | K11: =G11/(G11+H11) -> 0 | L11: =E11/(D11/1000000) -> 0.25730469 | M11: =G11/(D11/1000000) -> 0 | N11: U.S. Department of Education — EADA Survey Year 2024 | O11: Sun Belt Conference – 2023 Football Standings
A12: Texas State University | B12: West | C12: 120 | D12: 21622408 | E12: 8 | F12: 5 | G12: 4 | H12: 4 | I12: =D12/C12 -> 180186.73 | J12: =E12/(E12+F12) -> 0.61538462 | K12: =G12/(G12+H12) -> 0.5 | L12: =E12/(D12/1000000) -> 0.36998654 | M12: =G12/(D12/1000000) -> 0.18499327 | N12: U.S. Department of Education — EADA Survey Year 2024 | O12: Sun Belt Conference – 2023 Football Standings
A13: University of South Alabama | B13: West | C13: 122 | D13: 13932976 | E13: 7 | F13: 6 | G13: 4 | H13: 4 | I13: =D13/C13 -> 114204.72 | J13: =E13/(E13+F13) -> 0.53846154 | K13: =G13/(G13+H13) -> 0.5 | L13: =E13/(D13/1000000) -> 0.50240523 | M13: =G13/(D13/1000000) -> 0.2870887 | N13: U.S. Department of Education — EADA Survey Year 2024 | O13: Sun Belt Conference – 2023 Football Standings
... A15: Troy University | B15: West | C15: 129 | D15: 10281345 | E15: 11 | F15: 3 | G15: 7 | H15: 1 | I15: =D15/C15 -> 79700.349 | J15: =E15/(E15+F15) -> 0.78571429 | K15: =G15/(G15+H15) -> 0.875 | L15: =E15/(D15/1000000) -> 1.0698989 | M15: =G15/(D15/1000000) -> 0.68084477 | N15: U.S. Department of Education — EADA Survey Year 2024 | O15: Sun Belt Conference – 2023 Football Standings

Sheet analysis
A1: Metric | B1: Mean | C1: Median | D1: Minimum | E1: Maximum | F1: JMU | G1: JMU rank | J1: Correlation
A2: Total football expenses | B2: =AVERAGE(Data!D2:D15) -> 13576725 | C2: =MEDIAN(Data!D2:D15) -> 13429315 | D2: =MIN(Data!D2:D15) -> 7772886 | E2: =MAX(Data!D2:D15) -> 21622408 | F2: =Data!D7 -> 16863958 | G2: =_xlfn.RANK.EQ(Data!D7,Data!D2:D15)&"/14" -> 3/14 | I2: Total expenses vs overall win percentage | J2: =CORREL(Data!D2:D15,Data!J2:J15) -> 0.50643869
A3: Expenses per participant | B3: =AVERAGE(Data!I2:I15) -> 109165.64 | C3: =MEDIAN(Data!I2:I15) -> 106739.64 | D3: =MIN(Data!I2:I15) -> 66434.923 | E3: =MAX(Data!I2:I15) -> 180186.73 | F3: =Data!I7 -> 139371.55 | G3: =_xlfn.RANK.EQ(Data!I7,Data!I2:I15)&"/14" -> 2/14 | I3: Total expenses vs conference win percentage | J3: =CORREL(Data!D2:D15,Data!K2:K15) -> 0.40555342
A4: Overall win percentage | B4: =AVERAGE(Data!J2:J15) -> 0.52191261 | C4: =MEDIAN(Data!J2:J15) -> 0.5 | D4: =MIN(Data!J2:J15) -> 0.16666667 | E4: =MAX(Data!J2:J15) -> 0.84615385 | F4: =Data!J7 -> 0.84615385 | G4: =_xlfn.RANK.EQ(Data!J7,Data!J2:J15)&"/14" -> 1/14
A5: Conference win percentage | B5: =AVERAGE(Data!K2:K15) -> 0.5 | C5: =MEDIAN(Data!K2:K15) -> 0.5 | D5: =MIN(Data!K2:K15) -> 0 | E5: =MAX(Data!K2:K15) -> 0.875 | F5: =Data!K7 -> 0.875 | G5: =_xlfn.RANK.EQ(Data!K7,Data!K2:K15)&"/14" -> 1/14
A6: Wins per $1M spent | B6: =AVERAGE(Data!L2:L15) -> 0.51055415 | C6: =MEDIAN(Data!L2:L15) -> 0.4857712 | D6: =MIN(Data!L2:L15) -> 0.25730469 | E6: =MAX(Data!L2:L15) -> 1.0698989 | F6: =Data!L7 -> 0.65227866 | G6: =_xlfn.RANK.EQ(Data!L7,Data!L2:L15)&"/14" -> 3/14
A7: Conference wins per $1M | B7: =AVERAGE(Data!M2:M15) -> 0.29385277 | C7: =MEDIAN(Data!M2:M15) -> 0.27716939 | D7: =MIN(Data!M2:M15) -> 0 | E7: =MAX(Data!M2:M15) -> 0.68084477 | F7: =Data!M7 -> 0.41508642 | G7: =_xlfn.RANK.EQ(Data!M7,Data!M2:M15)&"/14" -> 3/14
A10: Key Findings
A11: 1. Large spending disparities
A12: Reported football expenses varied substantially across the Sun Belt, ranging from $7.8M at ULM to $21.6M at Texas State. The highest-spending program therefore spent approximately 2.8 times more than the lowest-spending program.
A14: 2. Spending was positively associated with performance, but the relationship was limited
A15: Total football expenses showed a moderate positive correlation with conference win percentage (r = 0.41). The linear model produced an R² of 0.16, indicating that the fitted linear relationship accounted for only a limited share of the observed variation in conference performance.
A17: 3. Troy achieved the strongest spending-adjusted conference performance
A18: Troy recorded 7 conference wins with $10.3M in reported football expenses, resulting in 0.68 conference wins per $1M spent — the highest value among the 14 Sun Belt programs analyzed.
A20: 4. JMU combined high spending with elite on-field performance
A21: JMU ranked 3rd in total football expenses, tied for 1st in conference win percentage at 87.5%, and ranked 3rd in conference wins per $1M spent. JMU therefore combined a high level of investment with both strong absolute and spending-adjusted performance.
A23: 5. Higher spending did not guarantee proportionally stronger results
A24: Texas State reported the highest football expenses in the conference at $21.6M but finished with a 50% conference win percentage and only 0.18 conference wins per $1M spent.
A26: Conclusion
A27: The 2023 Sun Belt data suggest that financial resources are associated with on-field performance, but spending alone does not explain success. Troy achieved the strongest results relative to its reported spending, while JMU combined one of the conference’s highest spending levels with elite performance and strong spending-adjusted outcomes. These findings should be interpreted as descriptive relationships rather than evidence of financial efficiency or causation.

Sheet dashboard
BF1: University | BG1: Total Football expenses
BF2: ULM | BG2: =Data!D11/1000000 -> 7.772886 | BH2: 7772886
BF3: Troy | BG3: =Data!D15/1000000 -> 10.281345 | BH3: 10281345
BF4: Southern Miss | BG4: =Data!D14/1000000 -> 11.033253 | BH4: 11033253
BF5: Georgia Southern | BG5: =Data!D5/1000000 -> 11.225441 | BH5: 11225441
BF6: Arkansas State | BG6: =Data!D3/1000000 -> 11.536628 | BH6: 11536628
BF7: Georgia State | BG7: =Data!D6/1000000 -> 12.26012 | BH7: 12260120
BF8: App State | BG8: =Data!D2/1000000 -> 13.288981 | BH8: 13288981
BF9: Marshall | BG9: =Data!D8/1000000 -> 13.569649 | BH9: 13569649
BF10: South Alabama | BG10: =Data!D13/1000000 -> 13.932976 | BH10: 13932976
BF11: ODU | BG11: =Data!D9/1000000 -> 14.787371 | BH11: 14787371
BF12: Louisiana | BG12: =Data!D10/1000000 -> 14.846554 | BH12: 14846554
BF13: JMU | BG13: =Data!D7/1000000 -> 16.863958 | BH13: 16863958
BF14: Coastal Carolina | BG14: =Data!D4/1000000 -> 17.052582 | BH14: 17052582
BF15: Texas State | BG15: =Data!D12/1000000 -> 21.622408 | BH15: 21622408
BF16: University | BG16: Total Football expenses | BH16: Conference Win Percentage
BF17: ULM | BG17: =Data!D11/1000000 -> 7.772886 | BH17: =Data!K11 -> 0
BF18: Troy | BG18: =Data!D15/1000000 -> 10.281345 | BH18: =Data!K15 -> 0.875
BF19: Southern Miss | BG19: =Data!D14/1000000 -> 11.033253 | BH19: =Data!K14 -> 0.25
BF20: Georgia Southern | BG20: =Data!D5/1000000 -> 11.225441 | BH20: =Data!K5 -> 0.375
BF21: Arkansas State | BG21: =Data!D3/1000000 -> 11.536628 | BH21: =Data!K3 -> 0.5
BF22: Georgia State | BG22: =Data!D6/1000000 -> 12.26012 | BH22: =Data!K6 -> 0.375
BF23: App State | BG23: =Data!D2/1000000 -> 13.288981 | BH23: =Data!K2 -> 0.75
BF24: Marshall | BG24: =Data!D8/1000000 -> 13.569649 | BH24: =Data!K8 -> 0.375
BF25: South Alabama | BG25: =Data!D13/1000000 -> 13.932976 | BH25: =Data!K13 -> 0.5
BF26: ODU | BG26: =Data!D9/1000000 -> 14.787371 | BH26: =Data!K9 -> 0.625
BF27: Louisiana | BG27: =Data!D10/1000000 -> 14.846554 | BH27: =Data!K10 -> 0.375
BF28: JMU | BG28: =Data!D7/1000000 -> 16.863958 | BH28: =Data!K7 -> 0.875
BF29: Coastal Carolina | BG29: =Data!D4/1000000 -> 17.052582 | BH29: =Data!K4 -> 0.625
BF30: Texas State | BG30: =Data!D12/1000000 -> 21.622408 | BH30: =Data!K12 -> 0.5
BG31: University | BH31: Conference Win Per 1M spent
BG32: ULM | BH32: =Data!M11 -> 0
BG33: Southern Miss | BH33: =Data!M14 -> 0.1812702
BG34: Texas State | BH34: =Data!M12 -> 0.18499327
BG35: Louisiana | BH35: =Data!M10 -> 0.20206709
BG36: Marshall | BH36: =Data!M8 -> 0.22108162
BG37: Georgia State | BH37: =Data!M6 -> 0.24469581
BG38: Georgia Southern | BH38: =Data!M5 -> 0.26725008
BG39: South Alabama | BH39: =Data!M13 -> 0.2870887
BG40: Coastal Carolina | BH40: =Data!M4 -> 0.29321073
...

Sheet Methodology & Sources
A1: Sun Belt Football Spending and Performance — Methodology & Sources
A3: 1. Research Question
A4: Which Sun Belt football programs achieved the strongest on-field performance relative to their reported spending during the 2023 season?
A7: 2. Scope
A8: Conference | C8: Sun Belt Conference
A9: Programs analyzed | C9: 14 football programs
A10: Football season | C10: 2023
A11: Financial dataset | C11: EADA Survey Year 2024
A12: Financial period | C12: Broadly corresponding to July 2023–June 2024
A13: Conference composition | C13: 2023 Sun Belt membership: Texas State included; Louisiana Tech excluded
A14: The EADA reporting period broadly overlaps with the 2023 football season. Individual institutions may use slightly different twelve-month reporting periods
A17: 3. Raw Variables
A18: Variable | B18: Definition | D18: Source
A19: Football participants | B19: Number of football participants reported by the institution | D19: EADA
A20: Total football expenses | B20: Total reported expenses attributed to the football program | D20: EADA
A21: Overall wins and losses | B21: Final overall 2023 season record, including postseason games | D21: Sun Belt
A22: Conference wins and losses | B22: 2023 regular-season Sun Belt record | D22: Sun Belt
A24: 4. Calculated Metrics
A25: Metric | C25: Formula
A26: Expenses per participant | C26: Total football expenses / Football participants
A27: Overall win percentage | C27: Overall wins / (Overall wins + Overall losses)
A28: Conference win percentage | C28: Conference wins / (Conference wins + Conference losses)
A29: Wins per $1M spent | C29: Overall wins / (Total football expenses / 1,000,000)
A30: Conference wins per $1M spent | C30: Conference wins / (Total football expenses / 1,000,000)
A32: 5. Correlation Analysis
A33: Relationship analyzed | C33: Total football expenses vs. conference win percentage
A34: Correlation coefficient | C34: =analysis!J3 -> 0.40555342
A35: R² | C35: =C34^2 -> 0.16447358
A36: The positive relationship is moderate. The R² value indicates that approximately 16% of the observed linear variation in conference win percentage is associated with differences in reported football spending within this sample. This result is descriptive and does not demonstrate causation.
A39: 6. Data Sources
A40: Source ID | B40: Source | C40: Variables used | D40: Link
A41: FIN-01 | B41: U.S. Department of Education — EADA Survey Year 2024 | C41: Football participants and total football expenses | D41: EADA official portal
A42: SPORT-01 | B42: Sun Belt Conference — 2023 Football Standings | C42: Overall and conference wins and losses | D42: 2023 Sun Belt standings
A43: RAW-01 | B43: EADA custom data export — Sport_Data_2024.csv | C43: Raw financial dataset retained with the project | D43: Embedded in workbook — Raw Data sheet
A45: 7. Limitations
A46: • The analysis covers only one football season.
A47: • Overall-season metrics are less directly comparable because programs played different numbers of games due to postseason participation; conference metrics are therefore emphasized in the main analysis.
A48: • The analysis covers all 14 Sun Belt football programs but only one conference and one season, limiting generalization to other conferences or years.
A49: • Strength of schedule is not controlled.
A50: • Injuries, coaching changes and roster quality are not included.
...

Sheet Raw Data
A1: Survey Year | B1: UNITID | C1: OPE ID | D1: Institution Name | E1: State CD | F1: Classification Name | G1: Classification Other | H1: Sanction Code | I1: Sanction Name | J1: Male Undergraduates | K1: Female Undergraduates | L1: Total Undergraduates | M1: Sport Code | N1: Sport Name | O1: # Participants Men's Team | P1: # Participants Women's Team | Q1: # Participants Men Coed Team | R1: # Participants Women Coed Team | S1: Total # Participants Men's Team/Men Coed Team | T1: Total # Participants Women's Team/Women Coed Team | U1: Operating Expenses per Participant/Men's Team | V1: Operating Expenses per Team/Men's Team | W1: Operating Expenses per Participant/Women's Team | X1: Operating Expenses per Team/Women's Team | Y1: Total Operating Expenses Men's Team and Women's Team | Z1: Operating Expenses per Participant/Men Coed Team | AA1: Operating Expenses per Team/Men Coed Team | AB1: Operating Expenses per Participant/Women Coed Team | AC1: Operating Expenses per Team/Women Coed Team | AD1: Total Operating Expenses Men Coed Team/Women Coed Team | AE1: Revenues Men's Team | AF1: Revenues Women's Team | AG1: Total Revenues For Men's Team and Women's Team | AH1: Revenues Men Coed Team | AI1: Revenues Women Coed Team | AJ1: Total Revenues Men Coed Team/Women Coed Team | AK1: Total Revenues Men's Team and Men Coed Team | AL1: Total Revenues Women's Team and Women Coed Team | AM1: Total Revenues Men's Team/Women's Team and Coed Team | AN1: Expenses Men's Team | AO1: Expenses Women's Team | AP1: Total Expenses Men's Team and Women's Team | AQ1: Expenses Men Coed Team | AR1: Expenses Women Coed Team | AS1: Total Expenses Men Coed Team and Women Coed Team | AT1: Total Expenses Men's Team and Men Coed Team | AU1: Total Expenses Women's Team and Women Coed Team | AV1: Total Expenses Men's Team/Women's Team and Coed Team
A2: 2024 | B2: 197869 | C2: 290600 | D2: Appalachian State University | E2: NC | F2: 1 | H2: 1 | I2: NCAA | J2: 8122 | K2: 9976 | L2: 18098 | M2: 7 | N2: Football | O2: 122 | S2: 122 | T2: 0 | U2: 18944 | V2: 2311199 | W2: 0 | X2: 0 | Y2: 2311199 | AE2: 13288981 | AG2: 13288981 | AK2: 13288981 | AL2: 0 | AM2: 13288981 | AN2: 13288981 | AP2: 13288981 | AT2: 13288981 | AU2: 0 | AV2: 13288981
A3: 2024 | B3: 106458 | C3: 109000 | D3: Arkansas State University | E3: AR | F3: 1 | H3: 1 | I3: NCAA | J3: 2210 | K3: 3310 | L3: 5520 | M3: 7 | N3: Football | O3: 153 | S3: 153 | T3: 0 | U3: 24612 | V3: 3765584 | W3: 0 | X3: 0 | Y3: 3765584 | AE3: 11536628 | AG3: 11536628 | AK3: 11536628 | AL3: 0 | AM3: 11536628 | AN3: 11536628 | AP3: 11536628 | AT3: 11536628 | AU3: 0 | AV3: 11536628
A4: 2024 | B4: 218724 | C4: 345100 | D4: Coastal Carolina University | E4: SC | F4: 1 | H4: 1 | I4: NCAA | J4: 4379 | K4: 5631 | L4: 10010 | M4: 7 | N4: Football | O4: 123 | S4: 123 | T4: 0 | U4: 19073 | V4: 2346000 | W4: 0 | X4: 0 | Y4: 2346000 | AE4: 17052582 | AG4: 17052582 | AK4: 17052582 | AL4: 0 | AM4: 17052582 | AN4: 17052582 | AP4: 17052582 | AT4: 17052582 | AU4: 0 | AV4: 17052582
A5: 2024 | B5: 139931 | C5: 157200 | D5: Georgia Southern University | E5: GA | F5: 1 | H5: 1 | I5: NCAA | J5: 8031 | K5: 10740 | L5: 18771 | M5: 7 | N5: Football | O5: 146 | S5: 146 | T5: 0 | U5: 13477 | V5: 1967592 | W5: 0 | X5: 0 | Y5: 1967592 | AE5: 11225441 | AG5: 11225441 | AK5: 11225441 | AL5: 0 | AM5: 11225441 | AN5: 11225441 | AP5: 11225441 | AT5: 11225441 | AU5: 0 | AV5: 11225441
A6: 2024 | B6: 139940 | C6: 157400 | D6: Georgia State University | E6: GA | F6: 1 | H6: 1 | I6: NCAA | J6: 8427 | K6: 11963 | L6: 20390 | M6: 7 | N6: Football | O6: 118 | S6: 118 | T6: 0 | U6: 17574 | V6: 2073699 | W6: 0 | X6: 0 | Y6: 2073699 | AE6: 12260120 | AG6: 12260120 | AK6: 12260120 | AL6: 0 | AM6: 12260120 | AN6: 12260120 | AP6: 12260120 | AT6: 12260120 | AU6: 0 | AV6: 12260120
A7: 2024 | B7: 232423 | C7: 372100 | D7: James Madison University | E7: VA | F7: 2 | H7: 1 | I7: NCAA | J7: 8602 | K7: 11174 | L7: 19776 | M7: 7 | N7: Football | O7: 121 | S7: 121 | T7: 0 | U7: 21974 | V7: 2658810 | W7: 0 | X7: 0 | Y7: 2658810 | AE7: 16863959 | AG7: 16863959 | AK7: 16863959 | AL7: 0 | AM7: 16863959 | AN7: 16863958 | AP7: 16863958 | AT7: 16863958 | AU7: 0 | AV7: 16863958
A8: 2024 | B8: 237525 | C8: 381500 | D8: Marshall University | E8: WV | F8: 1 | H8: 1 | I8: NCAA | J8: 2941 | K8: 3813 | L8: 6754 | M8: 7 | N8: Football | O8: 118 | S8: 118 | T8: 0 | U8: 30252 | V8: 3569751 | W8: 0 | X8: 0 | Y8: 3569751 | AE8: 13569649 | AG8: 13569649 | AK8: 13569649 | AL8: 0 | AM8: 13569649 | AN8: 13569649 | AP8: 13569649 | AT8: 13569649 | AU8: 0 | AV8: 13569649
A9: 2024 | B9: 232982 | C9: 372800 | D9: Old Dominion University | E9: VA | F9: 1 | H9: 1 | I9: NCAA | J9: 6238 | K9: 7336 | L9: 13574 | M9: 7 | N9: Football | O9: 116 | S9: 116 | T9: 0 | U9: 30610 | V9: 3550798 | W9: 0 | X9: 0 | Y9: 3550798 | AE9: 14787371 | AG9: 14787371 | AK9: 14787371 | AL9: 0 | AM9: 14787371 | AN9: 14787371 | AP9: 14787371 | AT9: 14787371 | AU9: 0 | AV9: 14787371
A10: 2024 | B10: 228459 | C10: 361500 | D10: Texas State University | E10: TX | F10: 1 | H10: 1 | I10: NCAA | J10: 12424 | K10: 18614 | L10: 31038 | M10: 7 | N10: Football | O10: 120 | S10: 120 | T10: 0 | U10: 37716 | V10: 4525910 | W10: 0 | X10: 0 | Y10: 4525910 | AE10: 21622408 | AG10: 21622408 | AK10: 21622408 | AL10: 0 | AM10: 21622408 | AN10: 21622408 | AP10: 21622408 | AT10: 21622408 | AU10: 0 | AV10: 21622408
A11: 2024 | B11: 102368 | C11: 104700 | D11: Troy University | E11: AL | F11: 1 | H11: 1 | I11: NCAA | J11: 2568 | K11: 4444 | L11: 7012 | M11: 7 | N11: Football | O11: 129 | S11: 129 | T11: 0 | U11: 9868 | V11: 1273008 | W11: 0 | X11: 0 | Y11: 1273008 | AE11: 12597439 | AG11: 12597439 | AK11: 12597439 | AL11: 0 | AM11: 12597439 | AN11: 10281345 | AP11: 10281345 | AT11: 10281345 | AU11: 0 | AV11: 10281345
A12: 2024 | B12: 160658 | C12: 203100 | D12: University of Louisiana at Lafayette | E12: LA | F12: 1 | H12: 1 | I12: NCAA | J12: 4676 | K12: 6570 | L12: 11246 | M12: 7 | N12: Football | O12: 142 | S12: 142 | T12: 0 | U12: 21786 | V12: 3093613 | W12: 0 | X12: 0 | Y12: 3093613 | AE12: 14846554 | AG12: 14846554 | AK12: 14846554 | AL12: 0 | AM12: 14846554 | AN12: 14846554 | AP12: 14846554 | AT12: 14846554 | AU12: 0 | AV12: 14846554
A13: 2024 | B13: 159993 | C13: 202000 | D13: University of Louisiana at Monroe | E13: LA | F13: 1 | H13: 1 | I13: NCAA | J13: 1563 | K13: 2557 | L13: 4120 | M13: 7 | N13: Football | O13: 117 | S13: 117 | T13: 0 | U13: 13029 | V13: 1524451 | W13: 0 | X13: 0 | Y13: 1524451 | AE13: 7772886 | AG13: 7772886 | AK13: 7772886 | AL13: 0 | AM13: 7772886 | AN13: 7772886 | AP13: 7772886 | AT13: 7772886 | AU13: 0 | AV13: 7772886
... A15: 2024 | B15: 176372 | C15: 244100 | D15: University of Southern Mississippi | E15: MS | F15: 1 | H15: 1 | I15: NCAA | J15: 3208 | K15: 5471 | L15: 8679 | M15: 7 | N15: Football | O15: 113 | S15: 113 | T15: 0 | U15: 17484 | V15: 1975712 | W15: 0 | X15: 0 | Y15: 1975712 | AE15: 11033253 | AG15: 11033253 | AK15: 11033253 | AL15: 0 | AM15: 11033253 | AN15: 11033253 | AP15: 11033253 | AT15: 11033253 | AU15: 0 | AV15: 11033253
